[22/09/2025 11:01:36] [ERROR] Risposta inattesa dal server Ollama (manca la chiave 'message').
[22/09/2025 11:11:01] [ERROR] Risposta inattesa dal server Ollama (manca la chiave 'message').
[22/09/2025 11:11:58] [ERROR] Risposta inattesa dal server Ollama (manca la chiave 'message').
[23/09/2025 08:04:50] [ERROR] Chiamata a Ollama fallita (host: http://192.168.1.13:11434, model: gemma2:2b) — model 'gemma2:2b' not found
[23/09/2025 08:08:28] [ERROR] Chiamata a Ollama fallita (host: http://192.168.1.13:11434, model: gemma2:2b) — model 'gemma2:2b' not found
[23/09/2025 08:16:46] [ERROR] Chiamata a Ollama fallita (host: http://192.168.1.13:11434, model: gemma2:2b) — model 'gemma2:2b' not found
[23/09/2025 08:17:03] [ERROR] Chiamata a Ollama fallita (host: http://192.168.1.13:11434, model: gemma2:2b) — model 'gemma2:2b' not found
[23/09/2025 13:20:13] [ERROR] Handler time_it.py ignorato: mancano funzioni can_handle/handle
[23/09/2025 13:21:44] [ERROR] Handler time_it.py ignorato: mancano funzioni can_handle/handle
[23/09/2025 13:22:37] [ERROR] Handler time_it.py ignorato: mancano funzioni can_handle/handle
[23/09/2025 13:23:48] [ERROR] Handler time_it.py ignorato: mancano funzioni can_handle/handle
[23/09/2025 13:26:02] [ERROR] Handler time_it.py ignorato: mancano funzioni can_handle/handle
[23/09/2025 13:32:04] [ERROR] Handler time_it.py ignorato: mancano funzioni can_handle/handle
[23/09/2025 13:36:16] [ERROR] Handler time_it.py ignorato: mancano funzioni can_handle/handle
[23/09/2025 13:37:40] [ERROR] Handler time_it.py ignorato: mancano funzioni can_handle/handle
[23/09/2025 13:39:26] [ERROR] Handler time_it.py ignorato: mancano funzioni can_handle/handle
[23/09/2025 13:42:47] [ERROR] Handler time_it.py ignorato: mancano funzioni can_handle/handle
[23/09/2025 13:47:49] [ERROR] Handler time_it.py ignorato: mancano funzioni can_handle/handle
[23/09/2025 13:47:50] [ERROR] Handler time_it.py ignorato: mancano funzioni can_handle/handle
[23/09/2025 13:55:36] [ERROR] Handler time_it.py ignorato: mancano funzioni can_handle/handle
[23/09/2025 13:59:04] [ERROR] Handler time_it.py ignorato: mancano funzioni can_handle/handle
[23/09/2025 13:59:12] [ERROR] Handler time_it.py ignorato: mancano funzioni can_handle/handle
[23/09/2025 14:07:47] [ERROR] Handler time_it.py ignorato: mancano funzioni can_handle/handle
[23/09/2025 14:12:39] [ERROR] Handler time_it.py ignorato: mancano funzioni can_handle/handle
[23/09/2025 14:14:37] [ERROR] Handler time_it.py ignorato: mancano funzioni can_handle/handle
[29/09/2025 14:11:12] [ERROR] Impossibile connettersi a Ollama su http://192.168.1.13:11434 — HTTPConnectionPool(host='192.168.1.13', port=11434): Max retries exceeded with url: /api/tags (Caused by NewConnectionError('<urllib3.connection.HTTPConnection object at 0x73b0454c1fa0>: Failed to establish a new connection: [Errno 113] No route to host'))
Verifica 'ollama serve', porta 11434 su 127.0.0.1 e valore 'ollama_host' nel config.
[29/09/2025 14:11:15] [ERROR] Impossibile connettersi a Ollama su http://192.168.1.13:11434 — HTTPConnectionPool(host='192.168.1.13', port=11434): Max retries exceeded with url: /api/tags (Caused by NewConnectionError('<urllib3.connection.HTTPConnection object at 0x73078200cb60>: Failed to establish a new connection: [Errno 113] No route to host'))
Verifica 'ollama serve', porta 11434 su 127.0.0.1 e valore 'ollama_host' nel config.
[29/09/2025 14:26:51] [ERROR] Chiamata a Ollama fallita (host: http://192.168.1.227:11434, model: gemma2:2b) — model 'gemma2:2b' not found
[29/09/2025 14:49:33] [ERROR] Chiamata a Ollama fallita (host: http://192.168.1.227:11434, model: gemma2:2b) — model 'gemma2:2b' not found
[06/10/2025 17:35:01] [ERROR] Impossibile connettersi a Ollama su http://192.168.1.227:11434 — HTTPConnectionPool(host='192.168.1.227', port=11434): Max retries exceeded with url: /api/tags (Caused by NewConnectionError('<urllib3.connection.HTTPConnection object at 0x7d9916274080>: Failed to establish a new connection: [Errno 113] No route to host'))
Verifica 'ollama serve', porta 11434 su 127.0.0.1 e valore 'ollama_host' nel config.
[06/10/2025 17:35:04] [ERROR] Impossibile connettersi a Ollama su http://192.168.1.227:11434 — HTTPConnectionPool(host='192.168.1.227', port=11434): Max retries exceeded with url: /api/tags (Caused by NewConnectionError('<urllib3.connection.HTTPConnection object at 0x7977dab50530>: Failed to establish a new connection: [Errno 113] No route to host'))
Verifica 'ollama serve', porta 11434 su 127.0.0.1 e valore 'ollama_host' nel config.
[09/10/2025 08:12:21] [ERROR] Impossibile connettersi a Ollama su http://127.0.0.1:11434 — HTTPConnectionPool(host='127.0.0.1', port=11434): Max retries exceeded with url: /api/tags (Caused by NewConnectionError('<urllib3.connection.HTTPConnection object at 0x79724a8adee0>: Failed to establish a new connection: [Errno 111] Connection refused'))
Verifica 'ollama serve', porta 11434 su 127.0.0.1 e valore 'ollama_host' nel config.
[09/10/2025 08:12:22] [ERROR] Impossibile connettersi a Ollama su http://127.0.0.1:11434 — HTTPConnectionPool(host='127.0.0.1', port=11434): Max retries exceeded with url: /api/tags (Caused by NewConnectionError('<urllib3.connection.HTTPConnection object at 0x7520a759aed0>: Failed to establish a new connection: [Errno 111] Connection refused'))
Verifica 'ollama serve', porta 11434 su 127.0.0.1 e valore 'ollama_host' nel config.
[11/10/2025 06:57:22] [ERROR] Impossibile connettersi a Ollama su http://127.0.0.1:11434 — HTTPConnectionPool(host='127.0.0.1', port=11434): Max retries exceeded with url: /api/tags (Caused by NewConnectionError('<urllib3.connection.HTTPConnection object at 0x7cd34fa8cec0>: Failed to establish a new connection: [Errno 111] Connection refused'))
Verifica 'ollama serve', porta 11434 su 127.0.0.1 e valore 'ollama_host' nel config.
[11/10/2025 06:57:22] [ERROR] Impossibile connettersi a Ollama su http://127.0.0.1:11434 — HTTPConnectionPool(host='127.0.0.1', port=11434): Max retries exceeded with url: /api/tags (Caused by NewConnectionError('<urllib3.connection.HTTPConnection object at 0x743f85f10dd0>: Failed to establish a new connection: [Errno 111] Connection refused'))
Verifica 'ollama serve', porta 11434 su 127.0.0.1 e valore 'ollama_host' nel config.
[11/10/2025 07:03:22] [ERROR] Errore durante il recupero modelli da http://127.0.0.1:11434 — HTTPConnectionPool(host='127.0.0.1', port=11434): Max retries exceeded with url: /api/tags (Caused by NewConnectionError('<urllib3.connection.HTTPConnection object at 0x743f85d883b0>: Failed to establish a new connection: [Errno 111] Connection refused'))
[11/10/2025 07:41:29] [ERROR] Errore durante il recupero modelli da http://127.0.0.1:11434 — HTTPConnectionPool(host='127.0.0.1', port=11434): Max retries exceeded with url: /api/tags (Caused by NewConnectionError('<urllib3.connection.HTTPConnection object at 0x743f85d887d0>: Failed to establish a new connection: [Errno 111] Connection refused'))
[12/10/2025 09:51:11] [ERROR] Impossibile connettersi a Ollama su http://127.0.0.1:11434 — HTTPConnectionPool(host='127.0.0.1', port=11434): Max retries exceeded with url: /api/tags (Caused by NewConnectionError('<urllib3.connection.HTTPConnection object at 0x7adc663ad760>: Failed to establish a new connection: [Errno 111] Connection refused'))
Verifica 'ollama serve', porta 11434 su 127.0.0.1 e valore 'ollama_host' nel config.
[12/10/2025 09:51:12] [ERROR] Impossibile connettersi a Ollama su http://127.0.0.1:11434 — HTTPConnectionPool(host='127.0.0.1', port=11434): Max retries exceeded with url: /api/tags (Caused by NewConnectionError('<urllib3.connection.HTTPConnection object at 0x7d53a9afce60>: Failed to establish a new connection: [Errno 111] Connection refused'))
Verifica 'ollama serve', porta 11434 su 127.0.0.1 e valore 'ollama_host' nel config.
[12/10/2025 10:54:06] [ERROR] Errore caricando handler command_mode.py: name 'os' is not defined
[12/10/2025 10:54:06] [ERROR] Errore caricando handler command_mode.py: name 'os' is not defined
[12/10/2025 15:50:08] [ERROR] Errore caricando handler command_mode.py: name 'os' is not defined
[12/10/2025 15:50:09] [ERROR] Errore caricando handler command_mode.py: name 'os' is not defined
[12/10/2025 15:52:13] [ERROR] Errore caricando handler command_mode.py: name 'os' is not defined
[12/10/2025 15:52:13] [ERROR] Errore caricando handler command_mode.py: name 'os' is not defined
[12/10/2025 15:52:44] [ERROR] Chiamata a Ollama fallita (host: http://127.0.0.1:11434, model: gemma2:2b) - model 'gemma2:2b' not found
[12/10/2025 15:57:29] [ERROR] Errore caricando handler command_mode.py: name 'COMMANDS_PATH' is not defined
[12/10/2025 15:57:42] [ERROR] Errore caricando handler command_mode.py: name 'COMMANDS_PATH' is not defined
[12/10/2025 15:57:42] [ERROR] Errore caricando handler command_mode.py: name 'COMMANDS_PATH' is not defined
[12/10/2025 15:57:57] [ERROR] Chiamata a Ollama fallita (host: http://127.0.0.1:11434, model: gemma2:2b) - model 'gemma2:2b' not found
[12/10/2025 16:05:35] [ERROR] Chiamata a Ollama fallita (host: http://127.0.0.1:11434, model: gemma2:2b) - model 'gemma2:2b' not found
[12/10/2025 16:06:11] [ERROR] Chiamata a Ollama fallita (host: http://127.0.0.1:11434, model: gemma2:2b) - model 'gemma2:2b' not found
[12/10/2025 16:06:33] [ERROR] Chiamata a Ollama fallita (host: http://127.0.0.1:11434, model: gemma2:2b) - model 'gemma2:2b' not found
[12/10/2025 16:12:55] [ERROR] Chiamata a Ollama fallita (host: http://127.0.0.1:11434, model: gemma2:2b) - model 'gemma2:2b' not found
[12/10/2025 16:20:25] [ERROR] Chiamata a Ollama fallita (host: http://127.0.0.1:11434, model: gemma2:2b) - model 'gemma2:2b' not found
[12/10/2025 16:25:04] [ERROR] Chiamata a Ollama fallita (host: http://127.0.0.1:11434, model: gemma2:2b) - model 'gemma2:2b' not found
[12/10/2025 16:25:40] [ERROR] Chiamata a Ollama fallita (host: http://127.0.0.1:11434, model: gemma2:2b) - model 'gemma2:2b' not found
[12/10/2025 16:25:58] [ERROR] Chiamata a Ollama fallita (host: http://127.0.0.1:11434, model: gemma2:2b) - model 'gemma2:2b' not found
[12/10/2025 16:41:55] [ERROR] Errore caricando handler command_mode.py: name 'COMMANDS_PATH' is not defined
[12/10/2025 16:42:07] [ERROR] Errore caricando handler command_mode.py: name 'COMMANDS_PATH' is not defined
[12/10/2025 16:42:08] [ERROR] Errore caricando handler command_mode.py: name 'COMMANDS_PATH' is not defined
[12/10/2025 16:46:18] [ERROR] Errore caricando handler present_robotics.py: (unicode error) 'utf-8' codec can't decode byte 0xe8 in position 9: invalid continuation byte (present_robotics.py, line 5)
[12/10/2025 16:46:18] [ERROR] Errore caricando handler command_mode.py: name 'COMMANDS_PATH' is not defined
[12/10/2025 16:46:18] [ERROR] Errore caricando handler present_robotics.py: (unicode error) 'utf-8' codec can't decode byte 0xe8 in position 9: invalid continuation byte (present_robotics.py, line 5)
[12/10/2025 16:46:18] [ERROR] Errore caricando handler command_mode.py: name 'COMMANDS_PATH' is not defined
[12/10/2025 16:47:57] [ERROR] Errore caricando handler present_robotics.py: (unicode error) 'utf-8' codec can't decode byte 0xe8 in position 9: invalid continuation byte (present_robotics.py, line 5)
[12/10/2025 16:47:57] [ERROR] Errore caricando handler command_mode.py: name 'COMMANDS_PATH' is not defined
[12/10/2025 16:47:58] [ERROR] Errore caricando handler present_robotics.py: (unicode error) 'utf-8' codec can't decode byte 0xe8 in position 9: invalid continuation byte (present_robotics.py, line 5)
[12/10/2025 16:47:58] [ERROR] Errore caricando handler command_mode.py: name 'COMMANDS_PATH' is not defined
[12/10/2025 17:01:18] [ERROR] Errore caricando handler present_robotics.py: (unicode error) 'utf-8' codec can't decode byte 0xe8 in position 9: invalid continuation byte (present_robotics.py, line 5)
[12/10/2025 17:01:18] [ERROR] Errore caricando handler command_mode.py: name 'COMMANDS_PATH' is not defined
[12/10/2025 17:01:18] [ERROR] Errore caricando handler present_robotics.py: (unicode error) 'utf-8' codec can't decode byte 0xe8 in position 9: invalid continuation byte (present_robotics.py, line 5)
[12/10/2025 17:01:18] [ERROR] Errore caricando handler command_mode.py: name 'COMMANDS_PATH' is not defined
[12/10/2025 19:27:47] [ERROR] Errore caricando handler present_robotics.py: (unicode error) 'utf-8' codec can't decode byte 0xe8 in position 9: invalid continuation byte (present_robotics.py, line 5)
[12/10/2025 19:27:47] [ERROR] Errore caricando handler command_mode.py: name 'COMMANDS_PATH' is not defined
[12/10/2025 19:27:47] [ERROR] Errore caricando handler present_robotics.py: (unicode error) 'utf-8' codec can't decode byte 0xe8 in position 9: invalid continuation byte (present_robotics.py, line 5)
[12/10/2025 19:27:47] [ERROR] Errore caricando handler command_mode.py: name 'COMMANDS_PATH' is not defined
[12/10/2025 20:02:37] [ERROR] Errore caricando handler present_robotics.py: (unicode error) 'utf-8' codec can't decode byte 0xe8 in position 9: invalid continuation byte (present_robotics.py, line 5)
[12/10/2025 20:02:37] [ERROR] Errore caricando handler command_mode.py: name 'COMMANDS_PATH' is not defined
[12/10/2025 20:02:38] [ERROR] Errore caricando handler present_robotics.py: (unicode error) 'utf-8' codec can't decode byte 0xe8 in position 9: invalid continuation byte (present_robotics.py, line 5)
[12/10/2025 20:02:38] [ERROR] Errore caricando handler command_mode.py: name 'COMMANDS_PATH' is not defined
[13/10/2025 14:23:10] [ERROR] Errore caricando handler present_robotics.py: (unicode error) 'utf-8' codec can't decode byte 0xe8 in position 9: invalid continuation byte (present_robotics.py, line 5)
[13/10/2025 14:23:10] [ERROR] Errore caricando handler command_mode.py: name 'COMMANDS_PATH' is not defined
[13/10/2025 14:23:10] [ERROR] Errore caricando handler present_robotics.py: (unicode error) 'utf-8' codec can't decode byte 0xe8 in position 9: invalid continuation byte (present_robotics.py, line 5)
[13/10/2025 14:23:10] [ERROR] Errore caricando handler command_mode.py: name 'COMMANDS_PATH' is not defined
[13/10/2025 14:39:34] [ERROR] Errore caricando handler present_robotics.py: (unicode error) 'utf-8' codec can't decode byte 0xe8 in position 9: invalid continuation byte (present_robotics.py, line 5)
[13/10/2025 14:39:34] [ERROR] Errore caricando handler command_mode.py: name 'COMMANDS_PATH' is not defined
[13/10/2025 14:39:34] [ERROR] Errore caricando handler present_robotics.py: (unicode error) 'utf-8' codec can't decode byte 0xe8 in position 9: invalid continuation byte (present_robotics.py, line 5)
[13/10/2025 14:39:34] [ERROR] Errore caricando handler command_mode.py: name 'COMMANDS_PATH' is not defined
[13/10/2025 14:57:46] [ERROR] Errore caricando handler present_robotics.py: invalid decimal literal (present_robotics.py, line 9)
[13/10/2025 14:57:46] [ERROR] Errore caricando handler command_mode.py: name 'COMMANDS_PATH' is not defined
[13/10/2025 14:58:46] [ERROR] Errore caricando handler present_robotics.py: invalid decimal literal (present_robotics.py, line 9)
[13/10/2025 14:58:46] [ERROR] Errore caricando handler command_mode.py: name 'COMMANDS_PATH' is not defined
[13/10/2025 14:59:08] [ERROR] Errore caricando handler present_robotics.py: (unicode error) 'utf-8' codec can't decode byte 0xe8 in position 9: invalid continuation byte (present_robotics.py, line 5)
[13/10/2025 14:59:08] [ERROR] Errore caricando handler command_mode.py: name 'COMMANDS_PATH' is not defined
[13/10/2025 16:54:29] [ERROR] Errore caricando handler present_robotics.py: (unicode error) 'utf-8' codec can't decode byte 0xe8 in position 9: invalid continuation byte (present_robotics.py, line 5)
[13/10/2025 16:54:29] [ERROR] Errore caricando handler command_mode.py: name 'COMMANDS_PATH' is not defined
[13/10/2025 16:54:30] [ERROR] Errore caricando handler present_robotics.py: (unicode error) 'utf-8' codec can't decode byte 0xe8 in position 9: invalid continuation byte (present_robotics.py, line 5)
[13/10/2025 16:54:30] [ERROR] Errore caricando handler command_mode.py: name 'COMMANDS_PATH' is not defined
[13/10/2025 19:43:53] [ERROR] Errore caricando handler present_robotics.py: (unicode error) 'utf-8' codec can't decode byte 0xe8 in position 9: invalid continuation byte (present_robotics.py, line 5)
[13/10/2025 19:43:53] [ERROR] Errore caricando handler command_mode.py: name 'COMMANDS_PATH' is not defined
[13/10/2025 19:43:53] [ERROR] Errore caricando handler present_robotics.py: (unicode error) 'utf-8' codec can't decode byte 0xe8 in position 9: invalid continuation byte (present_robotics.py, line 5)
[13/10/2025 19:43:53] [ERROR] Errore caricando handler command_mode.py: name 'COMMANDS_PATH' is not defined
[13/10/2025 19:51:46] [ERROR] Errore caricando handler present_robotics.py: (unicode error) 'utf-8' codec can't decode byte 0xe8 in position 9: invalid continuation byte (present_robotics.py, line 5)
[13/10/2025 19:51:46] [ERROR] Errore caricando handler command_mode.py: name 'COMMANDS_PATH' is not defined
[14/10/2025 07:33:10] [ERROR] Errore caricando handler present_robotics.py: (unicode error) 'utf-8' codec can't decode byte 0xe8 in position 9: invalid continuation byte (present_robotics.py, line 5)
[14/10/2025 07:33:10] [ERROR] Errore caricando handler command_mode.py: name 'COMMANDS_PATH' is not defined
[14/10/2025 07:33:10] [ERROR] Errore caricando handler present_robotics.py: (unicode error) 'utf-8' codec can't decode byte 0xe8 in position 9: invalid continuation byte (present_robotics.py, line 5)
[14/10/2025 07:33:10] [ERROR] Errore caricando handler command_mode.py: name 'COMMANDS_PATH' is not defined
[14/10/2025 07:42:57] [ERROR] Errore caricando handler present_robotics.py: (unicode error) 'utf-8' codec can't decode byte 0xe8 in position 9: invalid continuation byte (present_robotics.py, line 5)
[14/10/2025 07:42:57] [ERROR] Errore caricando handler command_mode.py: name 'COMMANDS_PATH' is not defined
[14/10/2025 07:42:58] [ERROR] Errore caricando handler present_robotics.py: (unicode error) 'utf-8' codec can't decode byte 0xe8 in position 9: invalid continuation byte (present_robotics.py, line 5)
[14/10/2025 07:42:58] [ERROR] Errore caricando handler command_mode.py: name 'COMMANDS_PATH' is not defined
[14/10/2025 07:55:02] [ERROR] Errore caricando handler present_robotics.py: (unicode error) 'utf-8' codec can't decode byte 0xe8 in position 9: invalid continuation byte (present_robotics.py, line 5)
[14/10/2025 07:55:02] [ERROR] Errore caricando handler command_mode.py: name 'COMMANDS_PATH' is not defined
[14/10/2025 07:55:03] [ERROR] Errore caricando handler present_robotics.py: (unicode error) 'utf-8' codec can't decode byte 0xe8 in position 9: invalid continuation byte (present_robotics.py, line 5)
[14/10/2025 07:55:03] [ERROR] Errore caricando handler command_mode.py: name 'COMMANDS_PATH' is not defined
[15/10/2025 07:11:29] [ERROR] Errore caricando handler present_robotics.py: (unicode error) 'utf-8' codec can't decode byte 0xe8 in position 9: invalid continuation byte (present_robotics.py, line 5)
[15/10/2025 07:11:29] [ERROR] Errore caricando handler command_mode.py: name 'COMMANDS_PATH' is not defined
[15/10/2025 07:11:29] [ERROR] Errore caricando handler present_robotics.py: (unicode error) 'utf-8' codec can't decode byte 0xe8 in position 9: invalid continuation byte (present_robotics.py, line 5)
[15/10/2025 07:11:29] [ERROR] Errore caricando handler command_mode.py: name 'COMMANDS_PATH' is not defined
[16/10/2025 06:38:25] [ERROR] Errore caricando handler present_robotics.py: (unicode error) 'utf-8' codec can't decode byte 0xe8 in position 9: invalid continuation byte (present_robotics.py, line 5)
[16/10/2025 06:38:25] [ERROR] Errore caricando handler command_mode.py: name 'COMMANDS_PATH' is not defined
[16/10/2025 06:38:25] [ERROR] Impossibile connettersi a Ollama su http://127.0.0.1:11434 - HTTPConnectionPool(host='127.0.0.1', port=11434): Max retries exceeded with url: /api/tags (Caused by NewConnectionError('<urllib3.connection.HTTPConnection object at 0x703d3b7f9bb0>: Failed to establish a new connection: [Errno 111] Connection refused'))
Verifica 'ollama serve', porta 11434 su 127.0.0.1 e valore 'ollama_host' nel config.
[16/10/2025 06:38:25] [ERROR] Errore caricando handler present_robotics.py: (unicode error) 'utf-8' codec can't decode byte 0xe8 in position 9: invalid continuation byte (present_robotics.py, line 5)
[16/10/2025 06:38:25] [ERROR] Errore caricando handler command_mode.py: name 'COMMANDS_PATH' is not defined
[16/10/2025 06:38:25] [ERROR] Impossibile connettersi a Ollama su http://127.0.0.1:11434 - HTTPConnectionPool(host='127.0.0.1', port=11434): Max retries exceeded with url: /api/tags (Caused by NewConnectionError('<urllib3.connection.HTTPConnection object at 0x73dc8b50b0e0>: Failed to establish a new connection: [Errno 111] Connection refused'))
Verifica 'ollama serve', porta 11434 su 127.0.0.1 e valore 'ollama_host' nel config.
[16/10/2025 06:40:56] [ERROR] Errore caricando handler present_robotics.py: (unicode error) 'utf-8' codec can't decode byte 0xe8 in position 9: invalid continuation byte (present_robotics.py, line 5)
[16/10/2025 06:40:56] [ERROR] Errore caricando handler command_mode.py: name 'COMMANDS_PATH' is not defined
[16/10/2025 06:40:56] [ERROR] Errore caricando handler present_robotics.py: (unicode error) 'utf-8' codec can't decode byte 0xe8 in position 9: invalid continuation byte (present_robotics.py, line 5)
[16/10/2025 06:40:56] [ERROR] Errore caricando handler command_mode.py: name 'COMMANDS_PATH' is not defined
[17/10/2025 07:54:57] [ERROR] Errore caricando handler present_robotics.py: (unicode error) 'utf-8' codec can't decode byte 0xe8 in position 9: invalid continuation byte (present_robotics.py, line 5)
[17/10/2025 07:54:57] [ERROR] Errore caricando handler command_mode.py: name 'COMMANDS_PATH' is not defined
[17/10/2025 07:55:00] [ERROR] Impossibile connettersi a Ollama su http://192.168.1.9:11434 - HTTPConnectionPool(host='192.168.1.9', port=11434): Max retries exceeded with url: /api/tags (Caused by NewConnectionError('<urllib3.connection.HTTPConnection object at 0x7007eaf176b0>: Failed to establish a new connection: [Errno 113] No route to host'))
Verifica 'ollama serve', porta 11434 su 127.0.0.1 e valore 'ollama_host' nel config.
[17/10/2025 07:57:03] [ERROR] Errore caricando handler present_robotics.py: (unicode error) 'utf-8' codec can't decode byte 0xe8 in position 9: invalid continuation byte (present_robotics.py, line 5)
[17/10/2025 07:57:03] [ERROR] Errore caricando handler command_mode.py: name 'COMMANDS_PATH' is not defined
[17/10/2025 07:57:06] [ERROR] Impossibile connettersi a Ollama su http://192.168.1.9:11434 - HTTPConnectionPool(host='192.168.1.9', port=11434): Max retries exceeded with url: /api/tags (Caused by NewConnectionError('<urllib3.connection.HTTPConnection object at 0x79f6c674b620>: Failed to establish a new connection: [Errno 113] No route to host'))
Verifica 'ollama serve', porta 11434 su 127.0.0.1 e valore 'ollama_host' nel config.
[17/10/2025 07:57:07] [ERROR] Errore caricando handler present_robotics.py: (unicode error) 'utf-8' codec can't decode byte 0xe8 in position 9: invalid continuation byte (present_robotics.py, line 5)
[17/10/2025 07:57:07] [ERROR] Errore caricando handler command_mode.py: name 'COMMANDS_PATH' is not defined
[17/10/2025 07:57:07] [ERROR] Impossibile connettersi a Ollama su http://192.168.1.9:11434 - HTTPConnectionPool(host='192.168.1.9', port=11434): Max retries exceeded with url: /api/tags (Caused by NewConnectionError('<urllib3.connection.HTTPConnection object at 0x7bc4c0187530>: Failed to establish a new connection: [Errno 113] No route to host'))
Verifica 'ollama serve', porta 11434 su 127.0.0.1 e valore 'ollama_host' nel config.
[17/10/2025 07:58:14] [ERROR] Errore durante il recupero modelli da http://192.168.1.9:11434 - HTTPConnectionPool(host='192.168.1.9', port=11434): Max retries exceeded with url: /api/tags (Caused by NewConnectionError('<urllib3.connection.HTTPConnection object at 0x7bc4c0243860>: Failed to establish a new connection: [Errno 113] No route to host'))
[17/10/2025 07:58:46] [ERROR] Errore caricando handler present_robotics.py: (unicode error) 'utf-8' codec can't decode byte 0xe8 in position 9: invalid continuation byte (present_robotics.py, line 5)
[17/10/2025 07:58:46] [ERROR] Errore caricando handler command_mode.py: name 'COMMANDS_PATH' is not defined
[17/10/2025 07:58:49] [ERROR] Impossibile connettersi a Ollama su http://192.168.1.9:11434 - HTTPConnectionPool(host='192.168.1.9', port=11434): Max retries exceeded with url: /api/tags (Caused by NewConnectionError('<urllib3.connection.HTTPConnection object at 0x7fd96deeb050>: Failed to establish a new connection: [Errno 113] No route to host'))
Verifica 'ollama serve', porta 11434 su 127.0.0.1 e valore 'ollama_host' nel config.
[17/10/2025 07:59:45] [ERROR] Errore caricando handler present_robotics.py: (unicode error) 'utf-8' codec can't decode byte 0xe8 in position 9: invalid continuation byte (present_robotics.py, line 5)
[17/10/2025 07:59:45] [ERROR] Errore caricando handler command_mode.py: name 'COMMANDS_PATH' is not defined
[17/10/2025 08:00:20] [ERROR] Errore caricando handler present_robotics.py: (unicode error) 'utf-8' codec can't decode byte 0xe8 in position 9: invalid continuation byte (present_robotics.py, line 5)
[17/10/2025 08:00:20] [ERROR] Errore caricando handler command_mode.py: name 'COMMANDS_PATH' is not defined
[17/10/2025 08:00:20] [ERROR] Errore caricando handler present_robotics.py: (unicode error) 'utf-8' codec can't decode byte 0xe8 in position 9: invalid continuation byte (present_robotics.py, line 5)
[17/10/2025 08:00:20] [ERROR] Errore caricando handler command_mode.py: name 'COMMANDS_PATH' is not defined
[17/10/2025 08:03:18] [ERROR] Errore caricando handler present_robotics.py: (unicode error) 'utf-8' codec can't decode byte 0xe8 in position 9: invalid continuation byte (present_robotics.py, line 5)
[17/10/2025 08:03:18] [ERROR] Errore caricando handler command_mode.py: name 'COMMANDS_PATH' is not defined
[17/10/2025 08:03:18] [ERROR] Errore caricando handler present_robotics.py: (unicode error) 'utf-8' codec can't decode byte 0xe8 in position 9: invalid continuation byte (present_robotics.py, line 5)
[17/10/2025 08:03:18] [ERROR] Errore caricando handler command_mode.py: name 'COMMANDS_PATH' is not defined
[17/10/2025 18:59:44] [ERROR] Errore caricando handler present_robotics.py: (unicode error) 'utf-8' codec can't decode byte 0xe8 in position 9: invalid continuation byte (present_robotics.py, line 5)
[17/10/2025 18:59:44] [ERROR] Errore caricando handler command_mode.py: name 'COMMANDS_PATH' is not defined
[17/10/2025 18:59:44] [ERROR] Errore caricando handler present_robotics.py: (unicode error) 'utf-8' codec can't decode byte 0xe8 in position 9: invalid continuation byte (present_robotics.py, line 5)
[17/10/2025 18:59:44] [ERROR] Errore caricando handler command_mode.py: name 'COMMANDS_PATH' is not defined
[18/10/2025 10:29:57] [ERROR] Errore caricando handler present_robotics.py: (unicode error) 'utf-8' codec can't decode byte 0xe8 in position 9: invalid continuation byte (present_robotics.py, line 5)
[18/10/2025 10:29:57] [ERROR] Errore caricando handler command_mode.py: name 'COMMANDS_PATH' is not defined
[18/10/2025 10:29:57] [ERROR] Errore caricando handler present_robotics.py: (unicode error) 'utf-8' codec can't decode byte 0xe8 in position 9: invalid continuation byte (present_robotics.py, line 5)
[18/10/2025 10:29:57] [ERROR] Errore caricando handler command_mode.py: name 'COMMANDS_PATH' is not defined
[18/10/2025 10:36:50] [ERROR] Errore caricando handler present_robotics.py: (unicode error) 'utf-8' codec can't decode byte 0xe8 in position 9: invalid continuation byte (present_robotics.py, line 5)
[18/10/2025 10:36:50] [ERROR] Errore caricando handler command_mode.py: name 'COMMANDS_PATH' is not defined
[18/10/2025 10:38:24] [ERROR] Errore caricando handler present_robotics.py: (unicode error) 'utf-8' codec can't decode byte 0xe8 in position 9: invalid continuation byte (present_robotics.py, line 5)
[18/10/2025 10:38:24] [ERROR] Errore caricando handler command_mode.py: name 'COMMANDS_PATH' is not defined
[18/10/2025 10:38:24] [ERROR] Errore caricando handler present_robotics.py: (unicode error) 'utf-8' codec can't decode byte 0xe8 in position 9: invalid continuation byte (present_robotics.py, line 5)
[18/10/2025 10:38:24] [ERROR] Errore caricando handler command_mode.py: name 'COMMANDS_PATH' is not defined
[18/10/2025 10:44:25] [ERROR] Errore caricando handler present_robotics.py: (unicode error) 'utf-8' codec can't decode byte 0xe8 in position 9: invalid continuation byte (present_robotics.py, line 5)
[18/10/2025 10:44:25] [ERROR] Errore caricando handler command_mode.py: name 'COMMANDS_PATH' is not defined
[18/10/2025 10:44:26] [ERROR] Errore caricando handler present_robotics.py: (unicode error) 'utf-8' codec can't decode byte 0xe8 in position 9: invalid continuation byte (present_robotics.py, line 5)
[18/10/2025 10:44:26] [ERROR] Errore caricando handler command_mode.py: name 'COMMANDS_PATH' is not defined
[18/10/2025 10:45:54] [ERROR] Errore caricando handler present_robotics.py: (unicode error) 'utf-8' codec can't decode byte 0xe8 in position 9: invalid continuation byte (present_robotics.py, line 5)
[18/10/2025 10:45:54] [ERROR] Errore caricando handler command_mode.py: name 'COMMANDS_PATH' is not defined
[18/10/2025 10:45:54] [ERROR] Errore caricando handler present_robotics.py: (unicode error) 'utf-8' codec can't decode byte 0xe8 in position 9: invalid continuation byte (present_robotics.py, line 5)
[18/10/2025 10:45:54] [ERROR] Errore caricando handler command_mode.py: name 'COMMANDS_PATH' is not defined
[18/10/2025 10:53:26] [ERROR] Errore caricando handler present_robotics.py: (unicode error) 'utf-8' codec can't decode byte 0xe8 in position 9: invalid continuation byte (present_robotics.py, line 5)
[18/10/2025 10:53:26] [ERROR] Errore caricando handler command_mode.py: name 'CONFIG_DIR' is not defined
[18/10/2025 10:53:26] [ERROR] Errore caricando handler present_robotics.py: (unicode error) 'utf-8' codec can't decode byte 0xe8 in position 9: invalid continuation byte (present_robotics.py, line 5)
[18/10/2025 10:53:26] [ERROR] Errore caricando handler command_mode.py: name 'CONFIG_DIR' is not defined
[18/10/2025 10:54:58] [ERROR] Errore caricando handler present_robotics.py: (unicode error) 'utf-8' codec can't decode byte 0xe8 in position 9: invalid continuation byte (present_robotics.py, line 5)
[18/10/2025 10:54:58] [ERROR] Errore caricando handler command_mode.py: unterminated string literal (detected at line 5) (command_mode.py, line 5)
[18/10/2025 10:54:59] [ERROR] Errore caricando handler present_robotics.py: (unicode error) 'utf-8' codec can't decode byte 0xe8 in position 9: invalid continuation byte (present_robotics.py, line 5)
[18/10/2025 10:54:59] [ERROR] Errore caricando handler command_mode.py: unterminated string literal (detected at line 5) (command_mode.py, line 5)
[18/10/2025 10:55:48] [ERROR] Errore caricando handler present_robotics.py: (unicode error) 'utf-8' codec can't decode byte 0xe8 in position 9: invalid continuation byte (present_robotics.py, line 5)
[18/10/2025 10:55:48] [ERROR] Errore caricando handler command_mode.py: name 'log_error' is not defined
[18/10/2025 10:55:49] [ERROR] Errore caricando handler present_robotics.py: (unicode error) 'utf-8' codec can't decode byte 0xe8 in position 9: invalid continuation byte (present_robotics.py, line 5)
[18/10/2025 10:55:49] [ERROR] Errore caricando handler command_mode.py: name 'log_error' is not defined
[18/10/2025 10:58:37] [ERROR] Errore caricando handler present_robotics.py: (unicode error) 'utf-8' codec can't decode byte 0xe8 in position 9: invalid continuation byte (present_robotics.py, line 5)
[18/10/2025 10:58:37] [ERROR] Handler command_mode.py ignorato: mancano funzioni can_handle/handle
[18/10/2025 10:58:37] [ERROR] Errore caricando handler present_robotics.py: (unicode error) 'utf-8' codec can't decode byte 0xe8 in position 9: invalid continuation byte (present_robotics.py, line 5)
[18/10/2025 10:58:37] [ERROR] Handler command_mode.py ignorato: mancano funzioni can_handle/handle
[18/10/2025 11:13:05] [ERROR] Errore caricando handler present_robotics.py: (unicode error) 'utf-8' codec can't decode byte 0xe8 in position 9: invalid continuation byte (present_robotics.py, line 5)
[18/10/2025 11:13:06] [ERROR] Errore caricando handler present_robotics.py: (unicode error) 'utf-8' codec can't decode byte 0xe8 in position 9: invalid continuation byte (present_robotics.py, line 5)
[18/10/2025 13:47:50] [ERROR] Errore caricando handler present_robotics.py: (unicode error) 'utf-8' codec can't decode byte 0xe8 in position 9: invalid continuation byte (present_robotics.py, line 5)
[18/10/2025 13:47:50] [ERROR] Errore caricando handler present_robotics.py: (unicode error) 'utf-8' codec can't decode byte 0xe8 in position 9: invalid continuation byte (present_robotics.py, line 5)
[18/10/2025 13:54:22] [ERROR] Errore caricando handler present_robotics.py: (unicode error) 'utf-8' codec can't decode byte 0xe8 in position 9: invalid continuation byte (present_robotics.py, line 5)
[18/10/2025 13:54:22] [ERROR] Errore caricando handler present_robotics.py: (unicode error) 'utf-8' codec can't decode byte 0xe8 in position 9: invalid continuation byte (present_robotics.py, line 5)
[18/10/2025 13:58:43] [ERROR] Errore caricando handler present_robotics.py: (unicode error) 'utf-8' codec can't decode byte 0xe8 in position 9: invalid continuation byte (present_robotics.py, line 5)
[18/10/2025 13:58:43] [ERROR] Errore caricando handler present_robotics.py: (unicode error) 'utf-8' codec can't decode byte 0xe8 in position 9: invalid continuation byte (present_robotics.py, line 5)
[19/10/2025 10:06:38] [ERROR] Errore caricando handler present_robotics.py: (unicode error) 'utf-8' codec can't decode byte 0xe8 in position 9: invalid continuation byte (present_robotics.py, line 5)
[19/10/2025 10:06:38] [ERROR] Errore caricando handler present_robotics.py: (unicode error) 'utf-8' codec can't decode byte 0xe8 in position 9: invalid continuation byte (present_robotics.py, line 5)
[19/10/2025 10:56:18] [ERROR] Errore caricando handler present_robotics.py: (unicode error) 'utf-8' codec can't decode byte 0xe8 in position 9: invalid continuation byte (present_robotics.py, line 5)
[19/10/2025 10:56:19] [ERROR] Errore caricando handler present_robotics.py: (unicode error) 'utf-8' codec can't decode byte 0xe8 in position 9: invalid continuation byte (present_robotics.py, line 5)
[19/10/2025 11:43:16] [ERROR] Chiamata a Ollama fallita (host: http://127.0.0.1:11434, model: gemma2:2b) - messages must contain content
[19/10/2025 11:43:56] [ERROR] Chiamata a Ollama fallita (host: http://127.0.0.1:11434, model: gemma2:2b) - messages must contain content
[19/10/2025 11:45:06] [ERROR] Errore caricando handler present_robotics.py: (unicode error) 'utf-8' codec can't decode byte 0xe8 in position 9: invalid continuation byte (present_robotics.py, line 5)
[19/10/2025 11:45:06] [ERROR] Errore caricando handler present_robotics.py: (unicode error) 'utf-8' codec can't decode byte 0xe8 in position 9: invalid continuation byte (present_robotics.py, line 5)
[19/10/2025 12:42:00] [ERROR] Chiamata a Ollama fallita (host: http://127.0.0.1:11434, model: gemma2:2b) - messages must contain content
[19/10/2025 12:58:17] [ERROR] Errore caricando handler present_robotics.py: (unicode error) 'utf-8' codec can't decode byte 0xe8 in position 9: invalid continuation byte (present_robotics.py, line 5)
[19/10/2025 12:59:47] [ERROR] Errore caricando handler present_robotics.py: (unicode error) 'utf-8' codec can't decode byte 0xe8 in position 9: invalid continuation byte (present_robotics.py, line 5)
[19/10/2025 13:21:04] [ERROR] Errore caricando handler present_robotics.py: (unicode error) 'utf-8' codec can't decode byte 0xe8 in position 9: invalid continuation byte (present_robotics.py, line 5)
[19/10/2025 13:22:12] [ERROR] Errore caricando handler present_robotics.py: (unicode error) 'utf-8' codec can't decode byte 0xe8 in position 9: invalid continuation byte (present_robotics.py, line 5)
[19/10/2025 13:47:09] [ERROR] Chiamata a Ollama fallita (host: http://127.0.0.1:11434, model: gemma2:2b) - messages must contain content
[19/10/2025 13:47:31] [ERROR] Chiamata a Ollama fallita (host: http://127.0.0.1:11434, model: gemma2:2b) - messages must contain content
[19/10/2025 13:56:25] [ERROR] Errore caricando handler present_robotics.py: (unicode error) 'utf-8' codec can't decode byte 0xe8 in position 9: invalid continuation byte (present_robotics.py, line 5)
[19/10/2025 13:57:30] [ERROR] Errore caricando handler present_robotics.py: (unicode error) 'utf-8' codec can't decode byte 0xe8 in position 9: invalid continuation byte (present_robotics.py, line 5)
[19/10/2025 14:00:18] [ERROR] Chiamata a Ollama fallita (host: http://127.0.0.1:11434, model: gemma2:2b) - messages must contain content
[19/10/2025 14:00:48] [ERROR] Chiamata a Ollama fallita (host: http://127.0.0.1:11434, model: gemma2:2b) - messages must contain content
[19/10/2025 14:17:19] [ERROR] Errore caricando handler present_robotics.py: (unicode error) 'utf-8' codec can't decode byte 0xe8 in position 9: invalid continuation byte (present_robotics.py, line 5)
[19/10/2025 14:53:45] [ERROR] Chiamata a Ollama fallita (host: http://127.0.0.1:11434, model: gemma2:2b) - messages must contain content
[19/10/2025 15:36:29] [ERROR] Chiamata a Ollama fallita (host: http://127.0.0.1:11434, model: gemma2:2b) - messages must contain content
[20/10/2025 06:01:33] [ERROR] Errore caricando handler present_robotics.py: (unicode error) 'utf-8' codec can't decode byte 0xe8 in position 9: invalid continuation byte (present_robotics.py, line 5)
[20/10/2025 06:01:33] [ERROR] Errore caricando handler present_robotics.py: (unicode error) 'utf-8' codec can't decode byte 0xe8 in position 9: invalid continuation byte (present_robotics.py, line 5)
[20/10/2025 06:10:20] [ERROR] Errore caricando handler present_robotics.py: (unicode error) 'utf-8' codec can't decode byte 0xe8 in position 9: invalid continuation byte (present_robotics.py, line 5)
[20/10/2025 06:10:20] [ERROR] Errore caricando handler present_robotics.py: (unicode error) 'utf-8' codec can't decode byte 0xe8 in position 9: invalid continuation byte (present_robotics.py, line 5)
